Workbook

Sheet Welcome
A1: FRAME RESTORATION UTAH
A2: Website Project Tracker
A5: Project: | B5: Frame Restoration Utah — Full Website Build
A6: Website: | B6: frame-restoration-utah.vercel.app
A7: Total Pages: | B7: 96 (62 Location + 16 Blog + 11 Service + Home + About + Contact + Gallery + FAQ + Careers + Privacy)
A8: Developer: | B8: Ryan Conwell
A9: Start Date:
A10: Target Launch:
A12: HOW TO USE THIS SHEET
A14: 1. | B14: Go to the "What I Need From You" tab — these are items I need from you to keep the project moving.
A15: 2. | B15: Go to the "Project Phases" tab — this shows every task and its current status.
A16: 3. | B16: Check "Page Photos & Content" — this is exactly what photos and text I need for each page.
A17: 4. | B17: Read "Brand & Blog Direction" — this is the messaging strategy for your entire site.
A18: 5. | B18: Check the Status column — items marked "Waiting on Client" need your attention.
A19: 6. | B19: Use the Notes column to leave me any comments or questions.
A20: 7. | B20: I'll update this sheet regularly so you always know where we stand.
A22: STATUS KEY
B24: Not Started
B25: In Progress
B26: Waiting on Client
B27: Complete
B28: N/A

Sheet What I Need From You
A1: WHAT I NEED FROM YOU
A2: These are items I need from you to build your website. Please review each item and provide what you can!
A3: # | B3: What I Need | C3: Details / Instructions | D3: Priority | E3: Status | F3: Due Date | G3: Your Notes
A4: BUSINESS INFORMATION
A5: 1 | B5: Business Legal Name | C5: Full legal name as registered | D5: High | E5: Waiting on Client
A6: 2 | B6: Business Phone Number | C6: Main number for website contact page & schema markup | D6: High | E6: Waiting on Client
A7: 3 | B7: Business Email Address | C7: Email for contact form submissions (Formspree) | D7: High | E7: Waiting on Client
A8: 4 | B8: Business Physical Address | C8: Full address for Google Maps embed and footer | D8: High | E8: Waiting on Client
A9: 5 | B9: Service Area / Regions | C9: List all cities and counties you serve (currently 62 location pages) | D9: High | E9: Waiting on Client
A10: 6 | B10: Business Hours | C10: Days & hours of operation for Schema.org markup | D10: Medium | E10: Waiting on Client
A11: 7 | B11: License & Insurance Info | C11: License numbers, insurance details for credibility section | D11: Medium | E11: Waiting on Client
A12: BRANDING & VISUALS
A13: 8 | B13: Company Logo (high-res) | C13: PNG with transparent background preferred. I'll create all color variants. | D13: High | E13: Waiting on Client
A14: 9 | B14: Brand Colors Preference | C14: Any specific colors you want? Current: Navy & Gold | D14: Medium | E14: Waiting on Client
A15: 10 | B15: Project Photos | C15: Before/after photos of your work — the more the better! Min 10-15 recommended. | D15: High | E15: Waiting on Client
A16: 11 | B16: Team / Owner Photo | C16: Professional headshot for About page (optional but builds trust) | D16: Low | E16: Waiting on Client
A17: WEBSITE CONTENT
A18: 12 | B18: About Us / Company Story | C18: Your company story, how you started, mission, values — a few paragraphs | D18: High | E18: Waiting on Client
A19: 13 | B19: List of All Services | C19: Every service you offer (e.g., frame repair, restoration, inspection, etc.) | D19: High | E19: Waiting on Client
A20: 14 | B20: Service Descriptions | C20: 2-3 sentences per service explaining what it includes | D20: High | E20: Waiting on Client
A21: 15 | B21: Pricing Info (if applicable) | C21: Do you want pricing on the site? Ranges? 'Call for quote'? | D21: Medium | E21: Waiting on Client
A22: 16 | B22: Customer Testimonials | C22: Written reviews or links to Google/Yelp reviews I can reference | D22: Medium | E22: Waiting on Client
A23: 17 | B23: FAQ Answers | C23: Common questions customers ask — I'll format them for the FAQ page | D23: Medium | E23: Waiting on Client
A24: 18 | B24: Blog Topic Ideas | C24: Any topics you want covered? Currently 16 blog posts planned. | D24: Low | E24: Waiting on Client
A25: ACCOUNTS & ACCESS
A26: 19 | B26: Google Business Profile | C26: Do you have one? I need access for reviews and local SEO | D26: High | E26: Waiting on Client
A27: 20 | B27: Domain Name | C27: Do you own a domain? If not, what domain do you want? | D27: High | E27: Waiting on Client
A28: 21 | B28: Google Analytics | C28: Do you have GA4 set up? If not, I'll set it up for you. | D28: Medium | E28: Waiting on Client
A29: 22 | B29: Social Media Links | C29: Facebook, Instagram, YouTube, etc. — any profiles to link to | D29: Low | E29: Waiting on Client
A30: FUNCTIONALITY PREFERENCES
A31: 23 | B31: Contact Form Fields | C31: What info do you want from leads? (Name, phone, email, service type, etc.) | D31: High | E31: Waiting on Client
A32: 24 | B32: Scheduling Preference | C32: Use Google Calendar booking? Phone calls only? Both? | D32: Medium | E32: Waiting on Client
A33: 25 | B33: Payment / Quotes | C33: Do you want online quote requests? Payment integration? | D33: Low | E33: Waiting on Client

Sheet Project Phases
A1: PROJECT PHASES & TASKS
A2: Full breakdown of every task in the website build. I'll keep this updated as we go.
A3: # | B3: Phase | C3: Task | D3: Details | E3: Status | F3: Owner | G3: Due Date | H3: Notes
A4: PHASE 1: DISCOVERY & PLANNING
A5: 1 | B5: Discovery | C5: Client Kickoff Call | D5: Discuss goals, services, target audience, competitors | E5: Complete | F5: Both
A6: 2 | B6: Discovery | C6: Gather Business Info | D6: Collect all business details (see 'What I Need' tab) | E6: In Progress | F6: Client
A7: 3 | B7: Discovery | C7: Competitor Research | D7: Analyze competitor websites in your market | E7: Complete | F7: Ryan
A8: 4 | B8: Discovery | C8: Site Map & Page Plan | D8: Plan all 96 pages — locations, services, blog, etc. | E8: Complete | F8: Ryan
A9: 5 | B9: Discovery | C9: Design Direction | D9: Agree on colors, fonts, style, and overall look & feel | E9: In Progress | F9: Both
A10: PHASE 2: DESIGN
A11: 6 | B11: Design | C11: Logo & Branding | D11: Create logo variants (wordmark-yellow, darkblue, white) | E11: Complete | F11: Ryan
A12: 7 | B12: Design | C12: Homepage Mockup | D12: Design homepage layout with hero, services, CTA sections | E12: Complete | F12: Ryan
A13: 8 | B13: Design | C13: Interior Page Templates | D13: Design templates for service, location, blog pages | E13: Complete | F13: Ryan
A14: 9 | B14: Design | C14: Mobile Responsive Design | D14: Ensure all pages work on phones and tablets | E14: In Progress | F14: Ryan
A15: 10 | B15: Design | C15: Client Design Approval | D15: Review and approve the overall design direction | E15: Waiting on Client | F15: Client
A16: PHASE 3: CONTENT CREATION
A17: 11 | B17: Content | C17: Homepage Copy | D17: Write hero text, service summaries, calls to action | E17: Complete | F17: Ryan
A18: 12 | B18: Content | C18: Service Pages (11) | D18: Write detailed content for each service page | E18: In Progress | F18: Ryan
A19: 13 | B19: Content | C19: Location Pages (62) | D19: Create unique content for each city/area page | E19: In Progress | F19: Ryan
A20: 14 | B20: Content | C20: Blog Articles (16) | D20: Write SEO-optimized blog posts for each topic | E20: In Progress | F20: Ryan
A21: 15 | B21: Content | C21: About Page | D21: Write company story — needs client input | E21: Waiting on Client | F21: Both
A22: 16 | B22: Content | C22: Photo Optimization | D22: Resize, compress, and optimize all project photos | E22: In Progress | F22: Ryan
A23: 17 | B23: Content | C23: Client Content Review | D23: Review all written content for accuracy | E23: Not Started | F23: Client
A24: PHASE 4: DEVELOPMENT
A25: 18 | B25: Development | C25: HTML/CSS Framework | D25: Build base HTML structure and CSS stylesheet | E25: Complete | F25: Ryan
A26: 19 | B26: Development | C26: Homepage Build | D26: Code the homepage with all sections | E26: Complete | F26: Ryan
A27: 20 | B27: Development | C27: Service Pages Build | D27: Code all 11 service page templates | E27: Complete | F27: Ryan
A28: 21 | B28: Development | C28: Location Pages Build | D28: Code all 62 location pages | E28: Complete | F28: Ryan
A29: 22 | B29: Development | C29: Blog Engine Build | D29: Code blog listing and individual post pages | E29: Complete | F29: Ryan
A30: 23 | B30: Development | C30: Contact Form (Formspree) | D30: Set up form submissions to client email | E30: In Progress | F30: Ryan
A31: 24 | B31: Development | C31: Google Calendar Integration | D31: Embed booking/scheduling functionality | E31: In Progress | F31: Ryan
A32: 25 | B32: Development | C32: Navigation & Footer | D32: Build responsive nav menu and footer with links | E32: Complete | F32: Ryan
A33: 26 | B33: Development | C33: Image Gallery | D33: Build project photo gallery page | E33: Complete | F33: Ryan
A34: PHASE 5: SEO & TECHNICAL
A35: 27 | B35: SEO | C35: Schema.org Structured Data | D35: Add LocalBusiness, Service, FAQ markup to all pages | E35: Complete | F35: Ryan
A36: 28 | B36: SEO | C36: Meta Tags & Descriptions | D36: Write unique title tags and meta descriptions per page | E36: In Progress | F36: Ryan
A37: 29 | B37: SEO | C37: XML Sitemap | D37: Generate and submit sitemap to Google | E37: Not Started | F37: Ryan
A38: 30 | B38: SEO | C38: Google Search Console | D38: Set up and verify site in Search Console | E38: Not Started | F38: Ryan
A39: 31 | B39: SEO | C39: Google Analytics (GA4) | D39: Install tracking code on all pages | E39: Not Started | F39: Ryan
A40: 32 | B40: SEO | C40: Page Speed Optimization | D40: Optimize images, CSS, loading performance | E40: In Progress | F40: Ryan
...

Sheet Page Photos & Content
A1: PAGE-BY-PAGE PHOTOS & CONTENT REQUIREMENTS
A2: Every page on your website — what photo goes where, what content needs your input, and what I need from you to make it real.
A3: # | B3: Page Name | C3: URL Path | D3: Current Photo | E3: Photo Needed | F3: Content Sections to Update | G3: What Client Should Provide | H3: Status | I3: Notes
A4: HOMEPAGE
A5: 1 | B5: Homepage | C5: / | D5: frame-restoration-17.jpg (hero) | E5: Hero: Dramatic before/after or crew on a roof. Gallery: 6-8 real project photos showing different services. | F5: Hero headline & subtext, 'Why Choose Us' section, service summaries, testimonial quotes, about preview paragraph | G5: 5-10 real project photos (before/after preferred), 3+ customer testimonials with names, your 'why' story (2-3 sentences) | H5: Waiting on Client
A6: SERVICE PAGES (11 pages — each has ONLY a hero background image, NO inline photos)
A7: 2 | B7: Residential Roofing | C7: /pages/residential-roofing | D7: frame-restoration-02.jpg | E7: Hero: Close-up of a completed residential shingle roof. Add 2-3 inline photos showing: 1) crew installing shingles, 2) finished roof on a Utah home, 3) before/after. | F7: Service descriptions (installation, replacement, repair, storm damage), materials offered, warranty info | G7: Photos of completed residential jobs, your preferred shingle brands, warranty details you offer | H7: Waiting on Client
A8: 3 | B8: Commercial Roofing | C8: /pages/commercial-roofing | D8: frame-restoration-09.jpg | E8: Hero: Large commercial building with flat or metal roof. Add 2-3 inline photos of commercial work — warehouse, office, retail. | F8: Commercial service descriptions, types of commercial roofs you do, project scale details | G8: Photos of commercial jobs, types of buildings you work on, any commercial certifications | H8: Waiting on Client
A9: 4 | B9: Storm Damage Restoration | C9: /pages/storm-damage-restoration | D9: frame-restoration-17.jpg | E9: Hero: Visible storm damage on a roof (hail dents, missing shingles). Add 2-3 inline: 1) hail damage close-up, 2) crew doing emergency work, 3) completed repair. | F9: Hail, wind, snow damage descriptions, insurance claim process details, emergency response info | G9: Storm damage photos (hail dents, wind damage, ice dams), your insurance claim process steps | H9: Waiting on Client
A10: 5 | B10: Roof Replacement | C10: /pages/roof-replacement | D10: frame-restoration-02.jpg (reused) | E10: Hero: Full tear-off in progress or brand new roof. NEEDS UNIQUE PHOTO — currently reusing residential-roofing hero. | F10: When replacement is needed vs repair, materials/brands, timeline expectations, cost factors | G10: Photos of a tear-off in progress and completed replacement, brands you carry, typical project timeline | H10: Waiting on Client
A11: 6 | B11: Roof Repair | C11: /pages/roof-repair | D11: frame-restoration-06.jpg | E11: Hero: Targeted repair work — patching, flashing fix, or leak repair. Add 1-2 inline showing specific repair types. | F11: Types of repairs you handle, emergency repair availability, common repair scenarios | G11: Photos of repair work (leak fixes, shingle replacement, flashing), your emergency response time | H11: Waiting on Client
A12: 7 | B12: Solar Installation | C12: /pages/solar-installation | D12: frame-restoration-14.jpg | E12: Hero: Solar panels on a Utah home with mountain backdrop. Add 2-3 inline: 1) installation process, 2) completed solar array, 3) roof prep for solar. | F12: Solar services offered, brands/equipment used, financing options, how it pairs with roof replacement | G12: Solar installation photos, brands/equipment you install, financing partners, any certifications | H12: Waiting on Client
A13: 8 | B13: Water Fire & Flood Restoration | C13: /pages/water-fire-flood-restoration | D13: frame-restoration-20.jpg | E13: Hero: Restoration work in progress (water extraction, fire cleanup). Add 2-3 inline showing different damage types. | F13: Water damage, fire damage, flood damage service descriptions, emergency response process | G13: Restoration project photos (water, fire, flood), your emergency response process, equipment used | H13: Waiting on Client
A14: 9 | B14: Insurance Claims | C14: /pages/insurance-claims | D14: frame-restoration-17.jpg (reused) | E14: Hero: Adjuster meeting on-site or documentation process. NEEDS UNIQUE PHOTO — currently reusing storm damage hero. | F14: Your insurance claim process, what you handle for the client, timeline, documentation approach | G14: Description of how you walk clients through claims, any success stats, common insurance questions | H14: Waiting on Client
A15: 10 | B15: Emergency Tarping | C15: /pages/emergency-tarping | D15: frame-restoration-06.jpg (reused) | E15: Hero: Emergency tarp on a damaged roof. NEEDS UNIQUE PHOTO — currently reusing roof repair hero. | F15: Emergency tarping service details, response time, what's included, when tarping is needed | G15: Emergency tarping photos, your typical response time, 24/7 availability confirmation | H15: Waiting on Client
A16: 11 | B16: General Contracting | C16: /pages/general-contracting | D16: frame-restoration-03.jpg | E16: Hero: General construction/renovation work. Add 2-3 inline showing variety: remodel, framing, exterior work. | F16: General contracting services, types of projects, capabilities beyond roofing | G16: Photos of non-roofing projects (additions, remodels, siding, etc.), scope of GC services | H16: Waiting on Client
A17: 12 | B17: Storm Damage (alternate) | C17: /pages/storm-damage | D17: frame-restoration-17.jpg (reused) | E17: Consider merging with /pages/storm-damage-restoration or redirecting. Currently a duplicate topic with different URL. | F17: Same as storm damage restoration — potential duplicate page to consolidate | G17: Confirm if this should be a separate page or redirect to storm-damage-restoration | H17: Waiting on Client
A18: BLOG POSTS (16 posts — each has ONE featured image inline in the article body)
A19: 13 | B19: Roof Repair vs Replacement - Bountiful | C19: /blog/bountiful/roof-repair-vs-replacement | D19: frame-restoration-06.jpg | E19: Featured image: Side-by-side showing a repaired section vs. a full new roof in Bountiful area. | F19: Repair vs replacement decision criteria — needs real local pricing, your professional recommendation | G19: Your rule of thumb for repair vs replace, typical Bountiful job costs, local examples | H19: Waiting on Client
A20: 14 | B20: Insurance Claims Storm Damage - Draper | C20: /blog/draper/insurance-claims-storm-damage | D20: frame-restoration-17.jpg | E20: Featured image: Insurance adjuster on a Draper roof with documentation in hand. | F20: Insurance claim walkthrough — needs your actual process steps, success stories | G20: Your step-by-step claim process, a client success story from Draper if possible | H20: Waiting on Client
A21: 15 | B21: Hail Damage New Homes - Herriman | C21: /blog/herriman/hail-damage-new-homes | D21: frame-restoration-12.jpg | E21: Featured image: Hail damage on a newer Herriman subdivision roof. | F21: Why new homes get hail damage — needs Herriman-specific weather data, your local experience | G21: Photos of hail damage on new Herriman homes, any stats on Herriman hail frequency | H21: Waiting on Client
A22: 16 | B22: Emergency Roof Tarping - Layton | C22: /blog/layton/emergency-roof-tarping | D22: frame-restoration-19.jpg | E22: Featured image: Emergency tarp installation on a Layton home, ideally during bad weather. | F22: Emergency tarping guide — needs your actual response process and local Layton context | G22: Emergency tarping photos, your response time to Layton, any Layton storm stories | H22: Waiting on Client
A23: 17 | B23: Hail Damage Roof Repair - Lehi | C23: /blog/lehi/hail-damage-roof-repair | D23: frame-restoration-12.jpg (reused) | E23: Featured image: Hail impact damage close-up on a Lehi roof. NEEDS UNIQUE PHOTO — reusing Herriman hail image. | F23: Lehi hail repair specifics — needs local weather patterns, your Lehi project experience | G23: Lehi hail damage photos (unique from Herriman post), local storm frequency info | H23: Waiting on Client
A24: 18 | B24: Signs You Need New Roof - Murray | C24: /blog/murray/signs-you-need-new-roof | D24: frame-restoration-06.jpg (reused) | E24: Featured image: Aging roof showing clear wear signs (curling shingles, moss, sagging). NEEDS UNIQUE PHOTO. | F24: Roof warning signs — needs your professional criteria for when a roof is done | G24: Photos showing roof aging/wear, your checklist for 'this roof needs replacing' | H24: Waiting on Client
A25: 19 | B25: Flat Roof Problems - Orem | C25: /blog/orem/flat-roof-problems-repair | D25: frame-restoration-15.jpg | E25: Featured image: Flat commercial/residential roof in Orem showing common issue (ponding, membrane damage). | F25: Flat roof problems & repair — needs Orem-specific building types, your flat roof expertise | G25: Flat roof project photos, common problems you see in Orem, repair methods you use | H25: Waiting on Client
A26: 20 | B26: Ice Dam Winter Damage - Park City | C26: /blog/park-city/ice-dam-winter-roof-damage | D26: frame-restoration-04.jpg | E26: Featured image: Ice dam on a Park City mountain home with icicles and snow load. | F26: Ice dam prevention & repair — needs Park City winter specifics, your ventilation approach | G26: Ice dam photos from Park City jobs, your prevention/fix process, ventilation recommendations | H26: Waiting on Client
A27: 21 | B27: Storm Damage Roof Repair - Provo | C27: /blog/provo/storm-damage-roof-repair | D27: frame-restoration-17.jpg (reused) | E27: Featured image: Storm-damaged roof in Provo. NEEDS UNIQUE PHOTO — reusing main storm damage image. | F27: Provo storm repair guide — needs local Provo weather patterns, your project examples | G27: Provo storm damage photos (unique), any Provo-specific project stories | H27: Waiting on Client
A28: 22 | B28: Older Home Roof Replacement - SLC | C28: /blog/salt-lake-city/older-home-roof-replacement | D28: frame-restoration-02.jpg (reused) | E28: Featured image: Older SLC home (Avenues, Sugar House era) getting new roof. NEEDS UNIQUE PHOTO. | F28: Older home challenges — needs SLC neighborhood specifics, historical home considerations | G28: Photos of older SLC home roof projects, challenges with 1920s-1960s homes, material recommendations | H28: Waiting on Client
A29: 23 | B29: Spring Hail Damage - Sandy | C29: /blog/sandy/spring-hail-damage-roof | D29: frame-restoration-12.jpg (reused) | E29: Featured image: Sandy east-bench home with hail damage after spring storm. NEEDS UNIQUE PHOTO. | F29: Sandy hail season — needs specific Sandy/east-bench weather data, your local experience | G29: Sandy hail damage photos (unique), Sandy storm season timing, east-bench specific risks | H29: Waiting on Client
A30: 24 | B30: Roof Leak After Rainstorm - West Jordan | C30: /blog/west-jordan/roof-leak-after-rainstorm | D30: frame-restoration-06.jpg (reused) | E30: Featured image: Interior ceiling water stain or active leak in a West Jordan home. NEEDS UNIQUE PHOTO. | F30: Leak diagnosis & repair — needs your troubleshooting process, common causes | G30: Leak/water damage photos (ceiling stains, attic moisture), your leak diagnosis process | H30: Waiting on Client
... A34: 28 | B34: Blog Index Page | C34: /blog/index.html | D34: No photo | E34: No hero image needed. Consider adding a banner image or featured post thumbnails to make it more visual. | F34: Blog listing layout — currently text-only. Could add category filters or featured post section. | G34: Confirm if you want blog categories, featured posts, or keep it simple | H34: Waiting on Client
A35: LOCATION PAGES (48 city hubs + ~288 sub-pages — hero image per page, all reuse from 24 photos)
A36: 29 | B36: Salt Lake City Hub | C36: /locations/salt-lake-city | D36: frame-restoration-02.jpg | E36: Hero: Iconic SLC skyline with mountains, or a completed roof job in SLC. Each of the 6 sub-pages also needs a hero. | F36: City intro, local stats, neighborhoods served, service descriptions — all need SLC-specific detail | G36: SLC project photos, neighborhoods you work in most, any SLC-specific certifications or partnerships | H36: Waiting on Client
A37: 30 | B37: Sandy Hub | C37: /locations/sandy | D37: frame-restoration-02.jpg (reused) | E37: Hero: Sandy east-bench neighborhood with Wasatch mountains. NEEDS UNIQUE PHOTO — currently same as SLC. | F37: Sandy-specific intro, local weather challenges, neighborhoods (Pepperwood, Dimple Dell, Alta Canyon) | G37: Sandy project photos (unique from SLC), Sandy neighborhoods you work in | H37: Waiting on Client
A38: 31 | B38: Draper Hub | C38: /locations/draper | D38: Uses one of 24 photos | E38: Hero: Draper neighborhood or Point of the Mountain area. Each location should feel distinct — not the same photo as Sandy/SLC. | F38: Draper-specific content, local neighborhoods, weather patterns unique to south valley | G38: Draper project photos, Draper neighborhoods you serve | H38: Waiting on Client
A39: 32 | B39: Park City Hub | C39: /locations/park-city | D39: Uses one of 24 photos | E39: Hero: Park City mountain home with snow or dramatic mountain backdrop. This location should feel premium/ski-town. | F39: Park City premium market positioning, mountain building codes, snow load requirements | G39: Park City project photos, experience with mountain/luxury homes, any PC contractor requirements | H39: Waiting on Client
A40: 33 | B40: All Other Location Hubs (44) | C40: Various — 44 more cities | D40: Rotating through 24 photos | E40: Each city hub needs its own distinct hero photo. Currently many share the same image. Ideally: local landmarks, neighborhood shots, or completed jobs in that city. | F40: Each page has city-specific intro, local stats, and service cards. Content is currently AI-generated and needs real local details. | G40: Project photos tagged by city (even phone photos help), any city-specific info or fun facts | H40: Waiting on Client
A41: LOCATION SUB-PAGES (~288 pages — 6 services x 48 cities, each with hero image)
A42: 34 | B42: Location Sub-Pages (All) | C42: e.g. /locations/sandy/residential-roofing | D42: Rotating through 24 photos | E42: Each sub-page uses one of 24 photos as hero. Content includes 5-step process, common problems list, FAQ. Most content is good but needs real client details for: pricing ranges, timeline estimates, and local-specific issues. | F42: 5-step process descriptions, common local problems, FAQ answers — currently templated, needs your real answers | G42: Your actual step-by-step process, real timeline estimates, real FAQ answers from customers | H42: Waiting on Client
A43: SITEWIDE ITEMS
...

Sheet Brand & Blog Direction
A1: BRAND MESSAGING & BLOG DIRECTION
A2: This defines how your brand sounds, looks, and communicates across every page — so everything feels like YOU, not generic AI content.
A3: Category | B3: Current Direction / Recommendation | C3: Your Input / Feedback
A4: BRAND VOICE & TONE
A5: Brand Personality | B5: Frame Restoration should come across as: professional but approachable, experienced but not arrogant, local and trustworthy. Think: the neighbor who happens to be an expert roofer. | C5: Does this match how you talk to customers? Any adjustments?
A6: Tone on Service Pages | B6: Confident, informative, action-oriented. Lead with what the customer gets, not what you do. Example: 'Your roof handles the worst of Utah weather — we make sure it keeps doing that.' NOT: 'We offer roofing services in Utah.' | C6: Review the example tone — does it sound like you?
A7: Tone on Blog Posts | B7: Educational, helpful, local-expert. Write like you're explaining things to a neighbor over the fence. Use specific Utah details (canyon winds, Wasatch hail, east-bench snow). Avoid salesy language in blog content. | C7: What questions do customers actually ask you? Those become blog topics.
A8: Tone on Location Pages | B8: Hyper-local and community-aware. Mention real neighborhoods, local landmarks, ZIP codes, and weather patterns specific to each city. Each city page should feel like you KNOW that area. | C8: For your top 5 cities — what neighborhoods do you work in most? Any local details?
A9: Words to Use | B9: Straightforward, honest, Utah-specific: 'Wasatch Front', 'canyon winds', 'east bench', 'free inspection', 'no surprises', 'we handle the insurance', 'your roof, our priority' | C9: Any phrases you use with customers that really resonate?
A10: Words to Avoid | B10: Avoid: 'synergy', 'leverage', 'solutions provider', 'world-class', 'cutting-edge'. Also avoid generic filler like 'in today's world' or 'when it comes to roofing'. Be specific, not fluffy. | C10: Any words or phrases you definitely do NOT want on the site?
A11: CORE MESSAGING PILLARS (these themes should show up on every page)
A12: Pillar 1: Insurance Made Easy | B12: You handle the entire insurance claim process. This is your biggest differentiator — most roofers don't do this. Every service page and blog post should mention insurance help. | C12: Is this accurate? How much of the claim do you handle vs. the homeowner?
A13: Pillar 2: Local Utah Experts | B13: You're not a national franchise — you live and work on the Wasatch Front. You know the weather, the neighborhoods, the building codes. This builds trust over out-of-state companies. | C13: How long have you been in Utah? Any specific Utah credentials or local partnerships?
A14: Pillar 3: No-Pressure Free Inspections | B14: Free roof inspections with no obligation. This is the primary conversion action on every page. Make it feel safe: 'We'll tell you what we see — no pressure, no surprise invoices.' | C14: Is 'free inspection' the main thing you want people to do on the site? Or call first?
A15: Pillar 4: Quality & Warranty | B15: You use top-tier materials (GAF, Owens Corning, CertainTeed) and provide real warranties. This separates you from low-bid contractors. | C15: What specific warranties do you offer? Manufacturer warranty + workmanship warranty?
A16: Pillar 5: Fast Emergency Response | B16: 24/7 emergency tarping and storm response. When a tree hits a roof or a storm rips off shingles, you're there fast. | C16: What's your actual emergency response time? Do you have a 24/7 phone line?
A17: BLOG CONTENT STRATEGY
A18: Blog Purpose | B18: Every blog post serves two jobs: (1) rank in Google for '[city] + [roofing topic]' searches, and (2) educate potential customers so they trust you enough to call. Posts should NOT be thinly disguised sales pitches. | C18: Any topics customers ask about that aren't covered in the current 16 posts?
A19: Current Blog Topics (16) | B19: Repair vs Replace (Bountiful), Insurance Claims (Draper), Hail on New Homes (Herriman), Emergency Tarping (Layton), Hail Repair (Lehi), Signs You Need New Roof (Murray), Flat Roof (Orem), Ice Dams (Park City), Storm Repair (Provo), Older Homes (SLC), Hail (Sandy), Leak After Rain (West Jordan), Cost Guide (WVC), Leak Repair (Sandy ZIP), Snow Damage (Heber) | C19: Are any of these topics wrong for your business? Any you'd remove or add?
A20: Blog Gaps — Recommended New Posts | B20: Missing topics: Solar + roof bundles, HOA roof requirements, metal roofing pros/cons, seasonal maintenance checklist, how to choose a roofer, commercial roof types, fire damage restoration guide, gutter & ventilation importance | C20: Which of these topics interest you? Any you'd prioritize?
A21: Blog Photo Strategy | B21: Each post needs ONE unique featured image. Currently many posts reuse the same 3-4 photos. City-specific posts should show that city — even a phone photo of a job in that neighborhood is better than a generic stock image. | C21: Can you start tagging project photos by city? Even rough phone photos work.
A22: Blog CTAs | B22: Every blog post ends with a gold CTA box: 'Schedule a Free Inspection'. This is consistent and good. Consider adding a secondary CTA for phone calls on mobile. | C22: Is the 'free inspection' CTA the right action for every post, or do some need 'call us' instead?
A23: VISUAL & PHOTO DIRECTION
A24: Photo Style | B24: Real project photos always beat stock. Even a phone photo of your crew on a roof beats a perfectly lit stock image. Authentic > polished. Show real Utah homes, real damage, real repairs. | C24: Are you comfortable taking photos on job sites? Phone photos are totally fine.
A25: Before/After Priority | B25: Before/after comparisons are the #1 most effective photos for roofing. Damaged roof → beautiful new roof. Try to capture these on every project, even quickly. | C25: Do you currently take before/after photos? Can you start?
A26: Photo Checklist per Job | B26: Ideal photo set per project: (1) Before/damage, (2) Crew working, (3) Materials/brand close-up, (4) Completed project, (5) Wide shot showing the full home. You don't need all 5 every time — any are helpful. | C26: Would a quick photo checklist card for your crew be helpful?
A27: Current Photo Inventory | B27: You have 24 photos (frame-restoration-01 through 24). These are being reused across 96+ pages. Goal: get to 50-75 unique photos so every page feels different. | C27: Can you gather 25-50 more photos from past and current projects?
A28: SEO CONTENT GUIDELINES (for consistent optimization across all pages)
A29: Title Tag Formula | B29: Service pages: '[Service] Utah | Frame Restoration Utah'. Location pages: '[Service] [City] UT | Frame Restoration'. Blog: '[Topic] in [City] | Frame Restoration Utah'. Keep under 60 characters. | C29: Review current title tags — any you'd change?
A30: Meta Description Formula | B30: 130-155 characters. Include: service name, city, one differentiator (insurance help, free inspection, etc.), phone number. Every page has a unique description. | C30: Do you want the phone number in every meta description?
A31: H1 Heading Rule | B31: One H1 per page. Service pages: '[Service] Across Utah'. Location pages: '[Service] in [City], UT'. Blog: topic-specific, keyword-rich. | C31: N/A — I'll handle this based on keyword research.
A32: Internal Linking | B32: Every page links to: (1) related service pages, (2) nearby location pages, (3) relevant blog posts. This helps Google understand your site structure and keeps visitors browsing. | C32: Any pages you think should link to each other that currently don't?
A33: Schema Markup | B33: Every page has structured data: Service schema, FAQPage schema, LocalBusiness, BlogPosting. This helps Google show rich results (star ratings, FAQ dropdowns, etc.). | C33: N/A — already implemented on all pages.

Sheet Progress
A1: PROJECT PROGRESS
B2: Count | C2: % of Total
A3: Total Tasks | B3: =COUNTA('Project Phases'!C4:C100) -> 46
A4: Complete | B4: =COUNTIF('Project Phases'!E4:E100,"Complete") -> 17 | C4: =IF(B3>0,B4/B3,"") -> 0.36956522
A5: In Progress | B5: =COUNTIF('Project Phases'!E4:E100,"In Progress") -> 11 | C5: =IF(B3>0,B5/B3,"") -> 0.23913043
A6: Waiting on Client | B6: =COUNTIF('Project Phases'!E4:E100,"Waiting on Client") -> 2 | C6: =IF(B3>0,B6/B3,"") -> 0.043478261
A7: Not Started | B7: =COUNTIF('Project Phases'!E4:E100,"Not Started") -> 16 | C7: =IF(B3>0,B7/B3,"") -> 0.34782609
A10: CLIENT ITEMS SUMMARY
B11: Count | C11: % of Total
A12: Total Items Needed | B12: =COUNTA('What I Need From You'!B4:B100) -> 25
A13: Provided (Complete) | B13: =COUNTIF('What I Need From You'!E4:E100,"Complete") -> 0 | C13: =IF(B12>0,B13/B12,"") -> 0
A14: Still Waiting | B14: =COUNTIF('What I Need From You'!E4:E100,"Waiting on Client") -> 25 | C14: =IF(B12>0,B14/B12,"") -> 1
A17: PAGE PHOTOS & CONTENT
B18: Count | C18: % of Total
A19: Total Page Items | B19: =COUNTA('Page Photos & Content'!B4:B200) -> 38
A20: Complete | B20: =COUNTIF('Page Photos & Content'!H4:H200,"Complete") -> 0 | C20: =IF(B19>0,B20/B19,"") -> 0
A21: Waiting on Client | B21: =COUNTIF('Page Photos & Content'!H4:H200,"Waiting on Client") -> 38 | C21: =IF(B19>0,B21/B19,"") -> 1
A22: In Progress | B22: =COUNTIF('Page Photos & Content'!H4:H200,"In Progress") -> 0 | C22: =IF(B19>0,B22/B19,"") -> 0
